2015-03-24 16:43:55,981 INFO [io.netty.handler.logging.LoggingHandler] [id: 0xc1dba3b4] REGISTERED
2015-03-24 16:43:55,984 INFO [io.netty.handler.logging.LoggingHandler] [id: 0xc1dba3b4] BIND: 0.0.0.0/0.0.0.0:8021
2015-03-24 16:43:55,988 INFO [io.netty.handler.logging.LoggingHandler] [id: 0xc1dba3b4, /0:0:0:0:0:0:0:0:8021] ACTIVE
2015-03-24 16:44:05,699 INFO [io.netty.handler.logging.LoggingHandler] [id: 0xc1dba3b4, /0:0:0:0:0:0:0:0:8021] RECEIVED: [id: 0xa91a3500, /127.0.0.1:63733 => /127.0.0.1:8021]
2015-03-24 16:44:19,875 WARN [io.netty.channel.DefaultChannelPipeline] An exceptionCaught() event was fired, and it reached at the tail of the pipeline. It usually means the last handler in the pipeline did not handle the exception.
java.io.IOException: 远程主机强迫关闭了一个现有的连接。
	at sun.nio.ch.SocketDispatcher.read0(Native Method)
	at sun.nio.ch.SocketDispatcher.read(Unknown Source)
	at sun.nio.ch.IOUtil.readIntoNativeBuffer(Unknown Source)
	at sun.nio.ch.IOUtil.read(Unknown Source)
	at sun.nio.ch.SocketChannelImpl.read(Unknown Source)
	at io.netty.buffer.PooledUnsafeDirectByteBuf.setBytes(PooledUnsafeDirectByteBuf.java:311)
	at io.netty.buffer.AbstractByteBuf.writeBytes(AbstractByteBuf.java:853)
	at io.netty.buffer.WrappedByteBuf.writeBytes(WrappedByteBuf.java:641)
	at io.netty.channel.socket.nio.NioSocketChannel.doReadBytes(NioSocketChannel.java:225)
	at io.netty.channel.nio.AbstractNioByteChannel$NioByteUnsafe.read(AbstractNioByteChannel.java:115)
	at io.netty.channel.nio.NioEventLoop.processSelectedKey(NioEventLoop.java:510)
	at io.netty.channel.nio.NioEventLoop.processSelectedKeysOptimized(NioEventLoop.java:467)
	at io.netty.channel.nio.NioEventLoop.processSelectedKeys(NioEventLoop.java:381)
	at io.netty.channel.nio.NioEventLoop.run(NioEventLoop.java:353)
	at io.netty.util.concurrent.SingleThreadEventExecutor$5.run(SingleThreadEventExecutor.java:834)
	at io.netty.util.concurrent.DefaultThreadFactory$DefaultRunnableDecorator.run(DefaultThreadFactory.java:137)
	at java.lang.Thread.run(Unknown Source)
2015-03-24 16:49:36,615 INFO [io.netty.handler.logging.LoggingHandler] [id: 0xa13f2b11] REGISTERED
2015-03-24 16:49:36,618 INFO [io.netty.handler.logging.LoggingHandler] [id: 0xa13f2b11] BIND: 0.0.0.0/0.0.0.0:8021
2015-03-24 16:49:36,623 INFO [io.netty.handler.logging.LoggingHandler] [id: 0xa13f2b11, /0:0:0:0:0:0:0:0:8021] ACTIVE
2015-03-24 16:49:46,417 INFO [io.netty.handler.logging.LoggingHandler] [id: 0xa13f2b11, /0:0:0:0:0:0:0:0:8021] RECEIVED: [id: 0x725eaac2, /127.0.0.1:63884 => /127.0.0.1:8021]
2015-03-24 16:50:36,420 WARN [io.netty.channel.DefaultChannelPipeline] An exceptionCaught() event was fired, and it reached at the tail of the pipeline. It usually means the last handler in the pipeline did not handle the exception.
io.netty.handler.timeout.ReadTimeoutException
2015-03-24 16:50:41,465 INFO [io.netty.handler.logging.LoggingHandler] [id: 0xa13f2b11, /0:0:0:0:0:0:0:0:8021] RECEIVED: [id: 0xbac0b7b6, /127.0.0.1:63891 => /127.0.0.1:8021]
2015-03-24 16:51:31,466 WARN [io.netty.channel.DefaultChannelPipeline] An exceptionCaught() event was fired, and it reached at the tail of the pipeline. It usually means the last handler in the pipeline did not handle the exception.
io.netty.handler.timeout.ReadTimeoutException
2015-03-24 16:51:36,468 INFO [io.netty.handler.logging.LoggingHandler] [id: 0xa13f2b11, /0:0:0:0:0:0:0:0:8021] RECEIVED: [id: 0x6e7abef5, /127.0.0.1:64992 => /127.0.0.1:8021]
2015-03-24 16:51:39,862 WARN [io.netty.channel.DefaultChannelPipeline] An exceptionCaught() event was fired, and it reached at the tail of the pipeline. It usually means the last handler in the pipeline did not handle the exception.
java.io.IOException: 远程主机强迫关闭了一个现有的连接。
	at sun.nio.ch.SocketDispatcher.read0(Native Method)
	at sun.nio.ch.SocketDispatcher.read(Unknown Source)
	at sun.nio.ch.IOUtil.readIntoNativeBuffer(Unknown Source)
	at sun.nio.ch.IOUtil.read(Unknown Source)
	at sun.nio.ch.SocketChannelImpl.read(Unknown Source)
	at io.netty.buffer.PooledUnsafeDirectByteBuf.setBytes(PooledUnsafeDirectByteBuf.java:311)
	at io.netty.buffer.AbstractByteBuf.writeBytes(AbstractByteBuf.java:853)
	at io.netty.channel.socket.nio.NioSocketChannel.doReadBytes(NioSocketChannel.java:225)
	at io.netty.channel.nio.AbstractNioByteChannel$NioByteUnsafe.read(AbstractNioByteChannel.java:115)
	at io.netty.channel.nio.NioEventLoop.processSelectedKey(NioEventLoop.java:510)
	at io.netty.channel.nio.NioEventLoop.processSelectedKeysOptimized(NioEventLoop.java:467)
	at io.netty.channel.nio.NioEventLoop.processSelectedKeys(NioEventLoop.java:381)
	at io.netty.channel.nio.NioEventLoop.run(NioEventLoop.java:353)
	at io.netty.util.concurrent.SingleThreadEventExecutor$5.run(SingleThreadEventExecutor.java:834)
	at io.netty.util.concurrent.DefaultThreadFactory$DefaultRunnableDecorator.run(DefaultThreadFactory.java:137)
	at java.lang.Thread.run(Unknown Source)
2015-03-24 16:52:07,155 INFO [io.netty.handler.logging.LoggingHandler] [id: 0x03af80d4] REGISTERED
2015-03-24 16:52:07,158 INFO [io.netty.handler.logging.LoggingHandler] [id: 0x03af80d4] BIND: 0.0.0.0/0.0.0.0:8021
2015-03-24 16:52:07,163 INFO [io.netty.handler.logging.LoggingHandler] [id: 0x03af80d4, /0:0:0:0:0:0:0:0:8021] ACTIVE
2015-03-24 16:52:13,749 INFO [io.netty.handler.logging.LoggingHandler] [id: 0x03af80d4, /0:0:0:0:0:0:0:0:8021] RECEIVED: [id: 0x721f6002, /127.0.0.1:65049 => /127.0.0.1:8021]
2015-03-24 16:52:50,197 WARN [io.netty.channel.DefaultChannelPipeline] An exceptionCaught() event was fired, and it reached at the tail of the pipeline. It usually means the last handler in the pipeline did not handle the exception.
java.io.IOException: 远程主机强迫关闭了一个现有的连接。
	at sun.nio.ch.SocketDispatcher.read0(Native Method)
	at sun.nio.ch.SocketDispatcher.read(Unknown Source)
	at sun.nio.ch.IOUtil.readIntoNativeBuffer(Unknown Source)
	at sun.nio.ch.IOUtil.read(Unknown Source)
	at sun.nio.ch.SocketChannelImpl.read(Unknown Source)
	at io.netty.buffer.PooledUnsafeDirectByteBuf.setBytes(PooledUnsafeDirectByteBuf.java:311)
	at io.netty.buffer.AbstractByteBuf.writeBytes(AbstractByteBuf.java:853)
	at io.netty.buffer.WrappedByteBuf.writeBytes(WrappedByteBuf.java:641)
	at io.netty.channel.socket.nio.NioSocketChannel.doReadBytes(NioSocketChannel.java:225)
	at io.netty.channel.nio.AbstractNioByteChannel$NioByteUnsafe.read(AbstractNioByteChannel.java:115)
	at io.netty.channel.nio.NioEventLoop.processSelectedKey(NioEventLoop.java:510)
	at io.netty.channel.nio.NioEventLoop.processSelectedKeysOptimized(NioEventLoop.java:467)
	at io.netty.channel.nio.NioEventLoop.processSelectedKeys(NioEventLoop.java:381)
	at io.netty.channel.nio.NioEventLoop.run(NioEventLoop.java:353)
	at io.netty.util.concurrent.SingleThreadEventExecutor$5.run(SingleThreadEventExecutor.java:834)
	at io.netty.util.concurrent.DefaultThreadFactory$DefaultRunnableDecorator.run(DefaultThreadFactory.java:137)
	at java.lang.Thread.run(Unknown Source)
2015-03-24 16:52:58,780 INFO [io.netty.handler.logging.LoggingHandler] [id: 0x03af80d4, /0:0:0:0:0:0:0:0:8021] RECEIVED: [id: 0xd6715c7f, /127.0.0.1:65073 => /127.0.0.1:8021]
2015-03-24 16:53:28,469 WARN [io.netty.channel.DefaultChannelPipeline] An exceptionCaught() event was fired, and it reached at the tail of the pipeline. It usually means the last handler in the pipeline did not handle the exception.
java.io.IOException: 远程主机强迫关闭了一个现有的连接。
	at sun.nio.ch.SocketDispatcher.read0(Native Method)
	at sun.nio.ch.SocketDispatcher.read(Unknown Source)
	at sun.nio.ch.IOUtil.readIntoNativeBuffer(Unknown Source)
	at sun.nio.ch.IOUtil.read(Unknown Source)
	at sun.nio.ch.SocketChannelImpl.read(Unknown Source)
	at io.netty.buffer.PooledUnsafeDirectByteBuf.setBytes(PooledUnsafeDirectByteBuf.java:311)
	at io.netty.buffer.AbstractByteBuf.writeBytes(AbstractByteBuf.java:853)
	at io.netty.channel.socket.nio.NioSocketChannel.doReadBytes(NioSocketChannel.java:225)
	at io.netty.channel.nio.AbstractNioByteChannel$NioByteUnsafe.read(AbstractNioByteChannel.java:115)
	at io.netty.channel.nio.NioEventLoop.processSelectedKey(NioEventLoop.java:510)
	at io.netty.channel.nio.NioEventLoop.processSelectedKeysOptimized(NioEventLoop.java:467)
	at io.netty.channel.nio.NioEventLoop.processSelectedKeys(NioEventLoop.java:381)
	at io.netty.channel.nio.NioEventLoop.run(NioEventLoop.java:353)
	at io.netty.util.concurrent.SingleThreadEventExecutor$5.run(SingleThreadEventExecutor.java:834)
	at io.netty.util.concurrent.DefaultThreadFactory$DefaultRunnableDecorator.run(DefaultThreadFactory.java:137)
	at java.lang.Thread.run(Unknown Source)
2015-03-24 16:57:36,742 INFO [io.netty.handler.logging.LoggingHandler] [id: 0x2c83cc9a] REGISTERED
2015-03-24 16:57:36,746 INFO [io.netty.handler.logging.LoggingHandler] [id: 0x2c83cc9a] BIND: 0.0.0.0/0.0.0.0:8021
2015-03-24 16:57:36,751 INFO [io.netty.handler.logging.LoggingHandler] [id: 0x2c83cc9a, /0:0:0:0:0:0:0:0:8021] ACTIVE
2015-03-24 16:57:42,062 INFO [io.netty.handler.logging.LoggingHandler] [id: 0x2c83cc9a, /0:0:0:0:0:0:0:0:8021] RECEIVED: [id: 0xf93fb59c, /127.0.0.1:63926 => /127.0.0.1:8021]
2015-03-24 16:57:52,939 WARN [io.netty.channel.DefaultChannelPipeline] An exceptionCaught() event was fired, and it reached at the tail of the pipeline. It usually means the last handler in the pipeline did not handle the exception.
java.io.IOException: 远程主机强迫关闭了一个现有的连接。
	at sun.nio.ch.SocketDispatcher.read0(Native Method)
	at sun.nio.ch.SocketDispatcher.read(Unknown Source)
	at sun.nio.ch.IOUtil.readIntoNativeBuffer(Unknown Source)
	at sun.nio.ch.IOUtil.read(Unknown Source)
	at sun.nio.ch.SocketChannelImpl.read(Unknown Source)
	at io.netty.buffer.PooledUnsafeDirectByteBuf.setBytes(PooledUnsafeDirectByteBuf.java:311)
	at io.netty.buffer.AbstractByteBuf.writeBytes(AbstractByteBuf.java:853)
	at io.netty.buffer.WrappedByteBuf.writeBytes(WrappedByteBuf.java:641)
	at io.netty.channel.socket.nio.NioSocketChannel.doReadBytes(NioSocketChannel.java:225)
	at io.netty.channel.nio.AbstractNioByteChannel$NioByteUnsafe.read(AbstractNioByteChannel.java:115)
	at io.netty.channel.nio.NioEventLoop.processSelectedKey(NioEventLoop.java:510)
	at io.netty.channel.nio.NioEventLoop.processSelectedKeysOptimized(NioEventLoop.java:467)
	at io.netty.channel.nio.NioEventLoop.processSelectedKeys(NioEventLoop.java:381)
	at io.netty.channel.nio.NioEventLoop.run(NioEventLoop.java:353)
	at io.netty.util.concurrent.SingleThreadEventExecutor$5.run(SingleThreadEventExecutor.java:834)
	at io.netty.util.concurrent.DefaultThreadFactory$DefaultRunnableDecorator.run(DefaultThreadFactory.java:137)
	at java.lang.Thread.run(Unknown Source)
2015-03-24 16:58:09,888 INFO [io.netty.handler.logging.LoggingHandler] [id: 0x11c85c98] REGISTERED
2015-03-24 16:58:09,891 INFO [io.netty.handler.logging.LoggingHandler] [id: 0x11c85c98] BIND: 0.0.0.0/0.0.0.0:8021
2015-03-24 16:58:09,896 INFO [io.netty.handler.logging.LoggingHandler] [id: 0x11c85c98, /0:0:0:0:0:0:0:0:8021] ACTIVE
2015-03-24 16:59:10,721 INFO [io.netty.handler.logging.LoggingHandler] [id: 0x11c85c98, /0:0:0:0:0:0:0:0:8021] RECEIVED: [id: 0xe8fa283d, /127.0.0.1:63990 => /127.0.0.1:8021]
2015-03-24 16:59:28,370 WARN [io.netty.channel.DefaultChannelPipeline] An exceptionCaught() event was fired, and it reached at the tail of the pipeline. It usually means the last handler in the pipeline did not handle the exception.
java.io.IOException: 远程主机强迫关闭了一个现有的连接。
	at sun.nio.ch.SocketDispatcher.read0(Native Method)
	at sun.nio.ch.SocketDispatcher.read(Unknown Source)
	at sun.nio.ch.IOUtil.readIntoNativeBuffer(Unknown Source)
	at sun.nio.ch.IOUtil.read(Unknown Source)
	at sun.nio.ch.SocketChannelImpl.read(Unknown Source)
	at io.netty.buffer.PooledUnsafeDirectByteBuf.setBytes(PooledUnsafeDirectByteBuf.java:311)
	at io.netty.buffer.AbstractByteBuf.writeBytes(AbstractByteBuf.java:853)
	at io.netty.buffer.WrappedByteBuf.writeBytes(WrappedByteBuf.java:641)
	at io.netty.channel.socket.nio.NioSocketChannel.doReadBytes(NioSocketChannel.java:225)
	at io.netty.channel.nio.AbstractNioByteChannel$NioByteUnsafe.read(AbstractNioByteChannel.java:115)
	at io.netty.channel.nio.NioEventLoop.processSelectedKey(NioEventLoop.java:510)
	at io.netty.channel.nio.NioEventLoop.processSelectedKeysOptimized(NioEventLoop.java:467)
	at io.netty.channel.nio.NioEventLoop.processSelectedKeys(NioEventLoop.java:381)
	at io.netty.channel.nio.NioEventLoop.run(NioEventLoop.java:353)
	at io.netty.util.concurrent.SingleThreadEventExecutor$5.run(SingleThreadEventExecutor.java:834)
	at io.netty.util.concurrent.DefaultThreadFactory$DefaultRunnableDecorator.run(DefaultThreadFactory.java:137)
	at java.lang.Thread.run(Unknown Source)
2015-03-24 16:59:34,673 INFO [io.netty.handler.logging.LoggingHandler] [id: 0x11c85c98, /0:0:0:0:0:0:0:0:8021] RECEIVED: [id: 0xbc61551b, /127.0.0.1:64011 => /127.0.0.1:8021]
2015-03-24 17:00:24,676 WARN [io.netty.channel.DefaultChannelPipeline] An exceptionCaught() event was fired, and it reached at the tail of the pipeline. It usually means the last handler in the pipeline did not handle the exception.
io.netty.handler.timeout.ReadTimeoutException
2015-03-24 17:00:29,696 INFO [io.netty.handler.logging.LoggingHandler] [id: 0x11c85c98, /0:0:0:0:0:0:0:0:8021] RECEIVED: [id: 0xfaf2a3e1, /127.0.0.1:64020 => /127.0.0.1:8021]
2015-03-24 17:01:18,456 WARN [io.netty.channel.DefaultChannelPipeline] An exceptionCaught() event was fired, and it reached at the tail of the pipeline. It usually means the last handler in the pipeline did not handle the exception.
java.io.IOException: 远程主机强迫关闭了一个现有的连接。
	at sun.nio.ch.SocketDispatcher.read0(Native Method)
	at sun.nio.ch.SocketDispatcher.read(Unknown Source)
	at sun.nio.ch.IOUtil.readIntoNativeBuffer(Unknown Source)
	at sun.nio.ch.IOUtil.read(Unknown Source)
	at sun.nio.ch.SocketChannelImpl.read(Unknown Source)
	at io.netty.buffer.PooledUnsafeDirectByteBuf.setBytes(PooledUnsafeDirectByteBuf.java:311)
	at io.netty.buffer.AbstractByteBuf.writeBytes(AbstractByteBuf.java:853)
	at io.netty.channel.socket.nio.NioSocketChannel.doReadBytes(NioSocketChannel.java:225)
	at io.netty.channel.nio.AbstractNioByteChannel$NioByteUnsafe.read(AbstractNioByteChannel.java:115)
	at io.netty.channel.nio.NioEventLoop.processSelectedKey(NioEventLoop.java:510)
	at io.netty.channel.nio.NioEventLoop.processSelectedKeysOptimized(NioEventLoop.java:467)
	at io.netty.channel.nio.NioEventLoop.processSelectedKeys(NioEventLoop.java:381)
	at io.netty.channel.nio.NioEventLoop.run(NioEventLoop.java:353)
	at io.netty.util.concurrent.SingleThreadEventExecutor$5.run(SingleThreadEventExecutor.java:834)
	at io.netty.util.concurrent.DefaultThreadFactory$DefaultRunnableDecorator.run(DefaultThreadFactory.java:137)
	at java.lang.Thread.run(Unknown Source)
2015-03-24 17:02:18,293 INFO [io.netty.handler.logging.LoggingHandler] [id: 0x11c85c98, /0:0:0:0:0:0:0:0:8021] RECEIVED: [id: 0xe7e2fa3a, /127.0.0.1:64048 => /127.0.0.1:8021]
2015-03-24 17:03:08,296 WARN [io.netty.channel.DefaultChannelPipeline] An exceptionCaught() event was fired, and it reached at the tail of the pipeline. It usually means the last handler in the pipeline did not handle the exception.
io.netty.handler.timeout.ReadTimeoutException
2015-03-24 17:04:13,018 WARN [io.netty.channel.DefaultChannelPipeline] An exceptionCaught() event was fired, and it reached at the tail of the pipeline. It usually means the last handler in the pipeline did not handle the exception.
io.netty.handler.timeout.ReadTimeoutException
2015-03-24 17:04:18,035 INFO [io.netty.handler.logging.LoggingHandler] [id: 0x11c85c98, /0:0:0:0:0:0:0:0:8021] RECEIVED: [id: 0x051aef92, /127.0.0.1:64062 => /127.0.0.1:8021]
2015-03-24 17:05:08,036 WARN [io.netty.channel.DefaultChannelPipeline] An exceptionCaught() event was fired, and it reached at the tail of the pipeline. It usually means the last handler in the pipeline did not handle the exception.
io.netty.handler.timeout.ReadTimeoutException
2015-03-24 17:05:13,039 INFO [io.netty.handler.logging.LoggingHandler] [id: 0x11c85c98, /0:0:0:0:0:0:0:0:8021] RECEIVED: [id: 0x33cc341f, /127.0.0.1:64068 => /127.0.0.1:8021]
2015-03-24 17:05:46,186 WARN [io.netty.channel.DefaultChannelPipeline] An exceptionCaught() event was fired, and it reached at the tail of the pipeline. It usually means the last handler in the pipeline did not handle the exception.
java.io.IOException: 远程主机强迫关闭了一个现有的连接。
	at sun.nio.ch.SocketDispatcher.read0(Native Method)
	at sun.nio.ch.SocketDispatcher.read(Unknown Source)
	at sun.nio.ch.IOUtil.readIntoNativeBuffer(Unknown Source)
	at sun.nio.ch.IOUtil.read(Unknown Source)
	at sun.nio.ch.SocketChannelImpl.read(Unknown Source)
	at io.netty.buffer.PooledUnsafeDirectByteBuf.setBytes(PooledUnsafeDirectByteBuf.java:311)
	at io.netty.buffer.AbstractByteBuf.writeBytes(AbstractByteBuf.java:853)
	at io.netty.channel.socket.nio.NioSocketChannel.doReadBytes(NioSocketChannel.java:225)
	at io.netty.channel.nio.AbstractNioByteChannel$NioByteUnsafe.read(AbstractNioByteChannel.java:115)
	at io.netty.channel.nio.NioEventLoop.processSelectedKey(NioEventLoop.java:510)
	at io.netty.channel.nio.NioEventLoop.processSelectedKeysOptimized(NioEventLoop.java:467)
	at io.netty.channel.nio.NioEventLoop.processSelectedKeys(NioEventLoop.java:381)
	at io.netty.channel.nio.NioEventLoop.run(NioEventLoop.java:353)
	at io.netty.util.concurrent.SingleThreadEventExecutor$5.run(SingleThreadEventExecutor.java:834)
	at io.netty.util.concurrent.DefaultThreadFactory$DefaultRunnableDecorator.run(DefaultThreadFactory.java:137)
	at java.lang.Thread.run(Unknown Source)
2015-03-24 17:06:12,717 INFO [io.netty.handler.logging.LoggingHandler] [id: 0x11c85c98, /0:0:0:0:0:0:0:0:8021] RECEIVED: [id: 0x975a807b, /127.0.0.1:64092 => /127.0.0.1:8021]
2015-03-24 17:06:14,977 WARN [io.netty.channel.DefaultChannelPipeline] An exceptionCaught() event was fired, and it reached at the tail of the pipeline. It usually means the last handler in the pipeline did not handle the exception.
java.io.IOException: 远程主机强迫关闭了一个现有的连接。
	at sun.nio.ch.SocketDispatcher.read0(Native Method)
	at sun.nio.ch.SocketDispatcher.read(Unknown Source)
	at sun.nio.ch.IOUtil.readIntoNativeBuffer(Unknown Source)
	at sun.nio.ch.IOUtil.read(Unknown Source)
	at sun.nio.ch.SocketChannelImpl.read(Unknown Source)
	at io.netty.buffer.PooledUnsafeDirectByteBuf.setBytes(PooledUnsafeDirectByteBuf.java:311)
	at io.netty.buffer.AbstractByteBuf.writeBytes(AbstractByteBuf.java:853)
	at io.netty.channel.socket.nio.NioSocketChannel.doReadBytes(NioSocketChannel.java:225)
	at io.netty.channel.nio.AbstractNioByteChannel$NioByteUnsafe.read(AbstractNioByteChannel.java:115)
	at io.netty.channel.nio.NioEventLoop.processSelectedKey(NioEventLoop.java:510)
	at io.netty.channel.nio.NioEventLoop.processSelectedKeysOptimized(NioEventLoop.java:467)
	at io.netty.channel.nio.NioEventLoop.processSelectedKeys(NioEventLoop.java:381)
	at io.netty.channel.nio.NioEventLoop.run(NioEventLoop.java:353)
	at io.netty.util.concurrent.SingleThreadEventExecutor$5.run(SingleThreadEventExecutor.java:834)
	at io.netty.util.concurrent.DefaultThreadFactory$DefaultRunnableDecorator.run(DefaultThreadFactory.java:137)
	at java.lang.Thread.run(Unknown Source)
2015-03-24 17:06:20,115 INFO [io.netty.handler.logging.LoggingHandler] [id: 0x11c85c98, /0:0:0:0:0:0:0:0:8021] RECEIVED: [id: 0x90896796, /127.0.0.1:64113 => /127.0.0.1:8021]
2015-03-24 17:06:46,215 WARN [io.netty.channel.DefaultChannelPipeline] An exceptionCaught() event was fired, and it reached at the tail of the pipeline. It usually means the last handler in the pipeline did not handle the exception.
java.io.IOException: 远程主机强迫关闭了一个现有的连接。
	at sun.nio.ch.SocketDispatcher.read0(Native Method)
	at sun.nio.ch.SocketDispatcher.read(Unknown Source)
	at sun.nio.ch.IOUtil.readIntoNativeBuffer(Unknown Source)
	at sun.nio.ch.IOUtil.read(Unknown Source)
	at sun.nio.ch.SocketChannelImpl.read(Unknown Source)
	at io.netty.buffer.PooledUnsafeDirectByteBuf.setBytes(PooledUnsafeDirectByteBuf.java:311)
	at io.netty.buffer.AbstractByteBuf.writeBytes(AbstractByteBuf.java:853)
	at io.netty.channel.socket.nio.NioSocketChannel.doReadBytes(NioSocketChannel.java:225)
	at io.netty.channel.nio.AbstractNioByteChannel$NioByteUnsafe.read(AbstractNioByteChannel.java:115)
	at io.netty.channel.nio.NioEventLoop.processSelectedKey(NioEventLoop.java:510)
	at io.netty.channel.nio.NioEventLoop.processSelectedKeysOptimized(NioEventLoop.java:467)
	at io.netty.channel.nio.NioEventLoop.processSelectedKeys(NioEventLoop.java:381)
	at io.netty.channel.nio.NioEventLoop.run(NioEventLoop.java:353)
	at io.netty.util.concurrent.SingleThreadEventExecutor$5.run(SingleThreadEventExecutor.java:834)
	at io.netty.util.concurrent.DefaultThreadFactory$DefaultRunnableDecorator.run(DefaultThreadFactory.java:137)
	at java.lang.Thread.run(Unknown Source)
2015-03-24 17:10:10,182 INFO [io.netty.handler.logging.LoggingHandler] [id: 0x1790d166] REGISTERED
2015-03-24 17:10:10,186 INFO [io.netty.handler.logging.LoggingHandler] [id: 0x1790d166] BIND: 0.0.0.0/0.0.0.0:8021
2015-03-24 17:10:10,190 INFO [io.netty.handler.logging.LoggingHandler] [id: 0x1790d166, /0:0:0:0:0:0:0:0:8021] ACTIVE
2015-03-24 17:10:17,390 INFO [io.netty.handler.logging.LoggingHandler] [id: 0x1790d166, /0:0:0:0:0:0:0:0:8021] RECEIVED: [id: 0x1f25c6c9, /127.0.0.1:64197 => /127.0.0.1:8021]
2015-03-24 17:11:07,390 WARN [io.netty.channel.DefaultChannelPipeline] An exceptionCaught() event was fired, and it reached at the tail of the pipeline. It usually means the last handler in the pipeline did not handle the exception.
io.netty.handler.timeout.ReadTimeoutException
2015-03-24 17:11:12,401 INFO [io.netty.handler.logging.LoggingHandler] [id: 0x1790d166, /0:0:0:0:0:0:0:0:8021] RECEIVED: [id: 0x425e1068, /127.0.0.1:64202 => /127.0.0.1:8021]
2015-03-24 17:12:02,405 WARN [io.netty.channel.DefaultChannelPipeline] An exceptionCaught() event was fired, and it reached at the tail of the pipeline. It usually means the last handler in the pipeline did not handle the exception.
io.netty.handler.timeout.ReadTimeoutException
2015-03-24 17:19:41,204 INFO [io.netty.handler.logging.LoggingHandler] [id: 0xcb56dccf] REGISTERED
2015-03-24 17:19:41,205 INFO [io.netty.handler.logging.LoggingHandler] [id: 0xcb56dccf] BIND: 0.0.0.0/0.0.0.0:8021
2015-03-24 17:19:41,210 INFO [io.netty.handler.logging.LoggingHandler] [id: 0xcb56dccf, /0:0:0:0:0:0:0:0:8021] ACTIVE
2015-03-24 17:21:58,957 INFO [io.netty.handler.logging.LoggingHandler] [id: 0xe1de3591] REGISTERED
2015-03-24 17:21:58,960 INFO [io.netty.handler.logging.LoggingHandler] [id: 0xe1de3591] BIND: 0.0.0.0/0.0.0.0:8021
2015-03-24 17:21:58,964 INFO [io.netty.handler.logging.LoggingHandler] [id: 0xe1de3591, /0:0:0:0:0:0:0:0:8021] ACTIVE
2015-03-24 17:22:04,707 INFO [io.netty.handler.logging.LoggingHandler] [id: 0xe1de3591, /0:0:0:0:0:0:0:0:8021] RECEIVED: [id: 0xd0cdfe89, /127.0.0.1:57026 => /127.0.0.1:8021]
2015-03-24 17:22:45,504 WARN [io.netty.channel.DefaultChannelPipeline] An exceptionCaught() event was fired, and it reached at the tail of the pipeline. It usually means the last handler in the pipeline did not handle the exception.
java.io.IOException: 远程主机强迫关闭了一个现有的连接。
	at sun.nio.ch.SocketDispatcher.read0(Native Method)
	at sun.nio.ch.SocketDispatcher.read(Unknown Source)
	at sun.nio.ch.IOUtil.readIntoNativeBuffer(Unknown Source)
	at sun.nio.ch.IOUtil.read(Unknown Source)
	at sun.nio.ch.SocketChannelImpl.read(Unknown Source)
	at io.netty.buffer.PooledUnsafeDirectByteBuf.setBytes(PooledUnsafeDirectByteBuf.java:311)
	at io.netty.buffer.AbstractByteBuf.writeBytes(AbstractByteBuf.java:853)
	at io.netty.channel.socket.nio.NioSocketChannel.doReadBytes(NioSocketChannel.java:225)
	at io.netty.channel.nio.AbstractNioByteChannel$NioByteUnsafe.read(AbstractNioByteChannel.java:115)
	at io.netty.channel.nio.NioEventLoop.processSelectedKey(NioEventLoop.java:510)
	at io.netty.channel.nio.NioEventLoop.processSelectedKeysOptimized(NioEventLoop.java:467)
	at io.netty.channel.nio.NioEventLoop.processSelectedKeys(NioEventLoop.java:381)
	at io.netty.channel.nio.NioEventLoop.run(NioEventLoop.java:353)
	at io.netty.util.concurrent.SingleThreadEventExecutor$5.run(SingleThreadEventExecutor.java:834)
	at io.netty.util.concurrent.DefaultThreadFactory$DefaultRunnableDecorator.run(DefaultThreadFactory.java:137)
	at java.lang.Thread.run(Unknown Source)
2015-03-24 17:22:59,816 INFO [io.netty.handler.logging.LoggingHandler] [id: 0x33403d4e] REGISTERED
2015-03-24 17:22:59,818 INFO [io.netty.handler.logging.LoggingHandler] [id: 0x33403d4e] BIND: 0.0.0.0/0.0.0.0:8021
2015-03-24 17:22:59,823 INFO [io.netty.handler.logging.LoggingHandler] [id: 0x33403d4e, /0:0:0:0:0:0:0:0:8021] ACTIVE
2015-03-24 17:23:04,530 INFO [io.netty.handler.logging.LoggingHandler] [id: 0x33403d4e, /0:0:0:0:0:0:0:0:8021] RECEIVED: [id: 0x76742a67, /127.0.0.1:57091 => /127.0.0.1:8021]
2015-03-24 17:23:08,444 WARN [io.netty.channel.DefaultChannelPipeline] An exceptionCaught() event was fired, and it reached at the tail of the pipeline. It usually means the last handler in the pipeline did not handle the exception.
java.io.IOException: 远程主机强迫关闭了一个现有的连接。
	at sun.nio.ch.SocketDispatcher.read0(Native Method)
	at sun.nio.ch.SocketDispatcher.read(Unknown Source)
	at sun.nio.ch.IOUtil.readIntoNativeBuffer(Unknown Source)
	at sun.nio.ch.IOUtil.read(Unknown Source)
	at sun.nio.ch.SocketChannelImpl.read(Unknown Source)
	at io.netty.buffer.PooledUnsafeDirectByteBuf.setBytes(PooledUnsafeDirectByteBuf.java:311)
	at io.netty.buffer.AbstractByteBuf.writeBytes(AbstractByteBuf.java:853)
	at io.netty.channel.socket.nio.NioSocketChannel.doReadBytes(NioSocketChannel.java:225)
	at io.netty.channel.nio.AbstractNioByteChannel$NioByteUnsafe.read(AbstractNioByteChannel.java:115)
	at io.netty.channel.nio.NioEventLoop.processSelectedKey(NioEventLoop.java:510)
	at io.netty.channel.nio.NioEventLoop.processSelectedKeysOptimized(NioEventLoop.java:467)
	at io.netty.channel.nio.NioEventLoop.processSelectedKeys(NioEventLoop.java:381)
	at io.netty.channel.nio.NioEventLoop.run(NioEventLoop.java:353)
	at io.netty.util.concurrent.SingleThreadEventExecutor$5.run(SingleThreadEventExecutor.java:834)
	at io.netty.util.concurrent.DefaultThreadFactory$DefaultRunnableDecorator.run(DefaultThreadFactory.java:137)
	at java.lang.Thread.run(Unknown Source)
2015-03-24 17:24:35,195 INFO [io.netty.handler.logging.LoggingHandler] [id: 0xa01dc5be] REGISTERED
2015-03-24 17:24:35,198 INFO [io.netty.handler.logging.LoggingHandler] [id: 0xa01dc5be] BIND: 0.0.0.0/0.0.0.0:8021
2015-03-24 17:24:35,202 INFO [io.netty.handler.logging.LoggingHandler] [id: 0xa01dc5be, /0:0:0:0:0:0:0:0:8021] ACTIVE
2015-03-24 17:24:40,922 INFO [io.netty.handler.logging.LoggingHandler] [id: 0xa01dc5be, /0:0:0:0:0:0:0:0:8021] RECEIVED: [id: 0xe473c11f, /127.0.0.1:57148 => /127.0.0.1:8021]
2015-03-24 17:25:05,958 INFO [io.netty.handler.logging.LoggingHandler] [id: 0xa01dc5be, /0:0:0:0:0:0:0:0:8021] RECEIVED: [id: 0xc25e743c, /127.0.0.1:57165 => /127.0.0.1:8021]
2015-03-24 17:25:30,925 WARN [io.netty.channel.DefaultChannelPipeline] An exceptionCaught() event was fired, and it reached at the tail of the pipeline. It usually means the last handler in the pipeline did not handle the exception.
io.netty.handler.timeout.ReadTimeoutException
2015-03-24 17:25:35,937 INFO [io.netty.handler.logging.LoggingHandler] [id: 0xa01dc5be, /0:0:0:0:0:0:0:0:8021] RECEIVED: [id: 0x87fd1c75, /127.0.0.1:57166 => /127.0.0.1:8021]
2015-03-24 17:25:44,839 WARN [io.netty.channel.DefaultChannelPipeline] An exceptionCaught() event was fired, and it reached at the tail of the pipeline. It usually means the last handler in the pipeline did not handle the exception.
java.io.IOException: 远程主机强迫关闭了一个现有的连接。
	at sun.nio.ch.SocketDispatcher.read0(Native Method)
	at sun.nio.ch.SocketDispatcher.read(Unknown Source)
	at sun.nio.ch.IOUtil.readIntoNativeBuffer(Unknown Source)
	at sun.nio.ch.IOUtil.read(Unknown Source)
	at sun.nio.ch.SocketChannelImpl.read(Unknown Source)
	at io.netty.buffer.PooledUnsafeDirectByteBuf.setBytes(PooledUnsafeDirectByteBuf.java:311)
	at io.netty.buffer.AbstractByteBuf.writeBytes(AbstractByteBuf.java:853)
	at io.netty.channel.socket.nio.NioSocketChannel.doReadBytes(NioSocketChannel.java:225)
	at io.netty.channel.nio.AbstractNioByteChannel$NioByteUnsafe.read(AbstractNioByteChannel.java:115)
	at io.netty.channel.nio.NioEventLoop.processSelectedKey(NioEventLoop.java:510)
	at io.netty.channel.nio.NioEventLoop.processSelectedKeysOptimized(NioEventLoop.java:467)
	at io.netty.channel.nio.NioEventLoop.processSelectedKeys(NioEventLoop.java:381)
	at io.netty.channel.nio.NioEventLoop.run(NioEventLoop.java:353)
	at io.netty.util.concurrent.SingleThreadEventExecutor$5.run(SingleThreadEventExecutor.java:834)
	at io.netty.util.concurrent.DefaultThreadFactory$DefaultRunnableDecorator.run(DefaultThreadFactory.java:137)
	at java.lang.Thread.run(Unknown Source)
2015-03-24 17:25:44,849 WARN [io.netty.channel.DefaultChannelPipeline] An exceptionCaught() event was fired, and it reached at the tail of the pipeline. It usually means the last handler in the pipeline did not handle the exception.
java.io.IOException: 远程主机强迫关闭了一个现有的连接。
	at sun.nio.ch.SocketDispatcher.read0(Native Method)
	at sun.nio.ch.SocketDispatcher.read(Unknown Source)
	at sun.nio.ch.IOUtil.readIntoNativeBuffer(Unknown Source)
	at sun.nio.ch.IOUtil.read(Unknown Source)
	at sun.nio.ch.SocketChannelImpl.read(Unknown Source)
	at io.netty.buffer.PooledUnsafeDirectByteBuf.setBytes(PooledUnsafeDirectByteBuf.java:311)
	at io.netty.buffer.AbstractByteBuf.writeBytes(AbstractByteBuf.java:853)
	at io.netty.channel.socket.nio.NioSocketChannel.doReadBytes(NioSocketChannel.java:225)
	at io.netty.channel.nio.AbstractNioByteChannel$NioByteUnsafe.read(AbstractNioByteChannel.java:115)
	at io.netty.channel.nio.NioEventLoop.processSelectedKey(NioEventLoop.java:510)
	at io.netty.channel.nio.NioEventLoop.processSelectedKeysOptimized(NioEventLoop.java:467)
	at io.netty.channel.nio.NioEventLoop.processSelectedKeys(NioEventLoop.java:381)
	at io.netty.channel.nio.NioEventLoop.run(NioEventLoop.java:353)
	at io.netty.util.concurrent.SingleThreadEventExecutor$5.run(SingleThreadEventExecutor.java:834)
	at io.netty.util.concurrent.DefaultThreadFactory$DefaultRunnableDecorator.run(DefaultThreadFactory.java:137)
	at java.lang.Thread.run(Unknown Source)
2015-03-24 17:26:38,478 INFO [io.netty.handler.logging.LoggingHandler] [id: 0xca6234f5] REGISTERED
2015-03-24 17:26:38,480 INFO [io.netty.handler.logging.LoggingHandler] [id: 0xca6234f5] BIND: 0.0.0.0/0.0.0.0:8021
2015-03-24 17:26:38,485 INFO [io.netty.handler.logging.LoggingHandler] [id: 0xca6234f5, /0:0:0:0:0:0:0:0:8021] ACTIVE
2015-03-24 17:26:42,517 INFO [io.netty.handler.logging.LoggingHandler] [id: 0xca6234f5, /0:0:0:0:0:0:0:0:8021] RECEIVED: [id: 0xab037a8f, /127.0.0.1:57224 => /127.0.0.1:8021]
2015-03-24 17:26:42,676 WARN [io.netty.channel.DefaultChannelPipeline] An exceptionCaught() event was fired, and it reached at the tail of the pipeline. It usually means the last handler in the pipeline did not handle the exception.
io.netty.handler.codec.DecoderException: java.lang.ClassCastException: java.lang.String cannot be cast to com.alibaba.fastjson.JSONObject
	at io.netty.handler.codec.ByteToMessageDecoder.callDecode(ByteToMessageDecoder.java:280)
	at io.netty.handler.codec.ByteToMessageDecoder.channelRead(ByteToMessageDecoder.java:149)
	at io.netty.channel.ChannelHandlerInvokerUtil.invokeChannelReadNow(ChannelHandlerInvokerUtil.java:83)
	at io.netty.channel.DefaultChannelHandlerInvoker.invokeChannelRead(DefaultChannelHandlerInvoker.java:153)
	at io.netty.channel.AbstractChannelHandlerContext.fireChannelRead(AbstractChannelHandlerContext.java:182)
	at io.netty.channel.DefaultChannelPipeline.fireChannelRead(DefaultChannelPipeline.java:886)
	at io.netty.channel.nio.AbstractNioByteChannel$NioByteUnsafe.read(AbstractNioByteChannel.java:126)
	at io.netty.channel.nio.NioEventLoop.processSelectedKey(NioEventLoop.java:510)
	at io.netty.channel.nio.NioEventLoop.processSelectedKeysOptimized(NioEventLoop.java:467)
	at io.netty.channel.nio.NioEventLoop.processSelectedKeys(NioEventLoop.java:381)
	at io.netty.channel.nio.NioEventLoop.run(NioEventLoop.java:353)
	at io.netty.util.concurrent.SingleThreadEventExecutor$5.run(SingleThreadEventExecutor.java:834)
	at io.netty.util.concurrent.DefaultThreadFactory$DefaultRunnableDecorator.run(DefaultThreadFactory.java:137)
	at java.lang.Thread.run(Unknown Source)
Caused by: java.lang.ClassCastException: java.lang.String cannot be cast to com.alibaba.fastjson.JSONObject
	at com.alibaba.fastjson.JSON.parseObject(JSON.java:169)
	at org.whale.inf.example.netty.common.NettyMessageDecoder.decode(NettyMessageDecoder.java:49)
	at io.netty.handler.codec.LengthFieldBasedFrameDecoder.decode(LengthFieldBasedFrameDecoder.java:343)
	at io.netty.handler.codec.ByteToMessageDecoder.callDecode(ByteToMessageDecoder.java:249)
	... 13 more
2015-03-24 17:27:13,541 INFO [io.netty.handler.logging.LoggingHandler] [id: 0xca6234f5, /0:0:0:0:0:0:0:0:8021] RECEIVED: [id: 0x467a5f16, /127.0.0.1:57242 => /127.0.0.1:8021]
2015-03-24 17:27:32,518 WARN [io.netty.channel.DefaultChannelPipeline] An exceptionCaught() event was fired, and it reached at the tail of the pipeline. It usually means the last handler in the pipeline did not handle the exception.
io.netty.handler.timeout.ReadTimeoutException
2015-03-24 17:27:32,522 WARN [io.netty.channel.DefaultChannelPipeline] An exceptionCaught() event was fired, and it reached at the tail of the pipeline. It usually means the last handler in the pipeline did not handle the exception.
io.netty.handler.codec.DecoderException: java.lang.IndexOutOfBoundsException
	at io.netty.handler.codec.ByteToMessageDecoder.channelInactive(ByteToMessageDecoder.java:213)
	at io.netty.channel.ChannelHandlerInvokerUtil.invokeChannelInactiveNow(ChannelHandlerInvokerUtil.java:56)
	at io.netty.channel.DefaultChannelHandlerInvoker.invokeChannelInactive(DefaultChannelHandlerInvoker.java:92)
	at io.netty.channel.AbstractChannelHandlerContext.fireChannelInactive(AbstractChannelHandlerContext.java:160)
	at io.netty.channel.DefaultChannelPipeline.fireChannelInactive(DefaultChannelPipeline.java:868)
	at io.netty.channel.AbstractChannel$AbstractUnsafe$5.run(AbstractChannel.java:604)
	at io.netty.util.concurrent.SingleThreadEventExecutor.runAllTasks(SingleThreadEventExecutor.java:343)
	at io.netty.channel.nio.NioEventLoop.run(NioEventLoop.java:356)
	at io.netty.util.concurrent.SingleThreadEventExecutor$5.run(SingleThreadEventExecutor.java:834)
	at io.netty.util.concurrent.DefaultThreadFactory$DefaultRunnableDecorator.run(DefaultThreadFactory.java:137)
	at java.lang.Thread.run(Unknown Source)
Caused by: java.lang.IndexOutOfBoundsException
	at io.netty.buffer.EmptyByteBuf.readInt(EmptyByteBuf.java:470)
	at org.whale.inf.example.netty.common.NettyMessageDecoder.decode(NettyMessageDecoder.java:27)
	at io.netty.handler.codec.LengthFieldBasedFrameDecoder.decode(LengthFieldBasedFrameDecoder.java:343)
	at io.netty.handler.codec.ByteToMessageDecoder.decodeLast(ByteToMessageDecoder.java:304)
	at io.netty.handler.codec.ByteToMessageDecoder.channelInactive(ByteToMessageDecoder.java:208)
	... 10 more
2015-03-24 17:27:32,527 WARN [io.netty.channel.DefaultChannelPipeline] An exceptionCaught() event was fired, and it reached at the tail of the pipeline. It usually means the last handler in the pipeline did not handle the exception.
io.netty.handler.codec.TooLongFrameException: Adjusted frame length exceeds 1048576: 1885434747 - discarded
	at io.netty.handler.codec.LengthFieldBasedFrameDecoder.fail(LengthFieldBasedFrameDecoder.java:501)
	at io.netty.handler.codec.LengthFieldBasedFrameDecoder.failIfNecessary(LengthFieldBasedFrameDecoder.java:477)
	at io.netty.handler.codec.LengthFieldBasedFrameDecoder.decode(LengthFieldBasedFrameDecoder.java:403)
	at org.whale.inf.example.netty.common.NettyMessageDecoder.decode(NettyMessageDecoder.java:21)
	at io.netty.handler.codec.LengthFieldBasedFrameDecoder.decode(LengthFieldBasedFrameDecoder.java:343)
	at io.netty.handler.codec.ByteToMessageDecoder.callDecode(ByteToMessageDecoder.java:249)
	at io.netty.handler.codec.ByteToMessageDecoder.channelInactive(ByteToMessageDecoder.java:205)
	at io.netty.channel.ChannelHandlerInvokerUtil.invokeChannelInactiveNow(ChannelHandlerInvokerUtil.java:56)
	at io.netty.channel.DefaultChannelHandlerInvoker.invokeChannelInactive(DefaultChannelHandlerInvoker.java:92)
	at io.netty.channel.AbstractChannelHandlerContext.fireChannelInactive(AbstractChannelHandlerContext.java:160)
	at io.netty.channel.DefaultChannelPipeline.fireChannelInactive(DefaultChannelPipeline.java:868)
	at io.netty.channel.AbstractChannel$AbstractUnsafe$5.run(AbstractChannel.java:604)
	at io.netty.util.concurrent.SingleThreadEventExecutor.runAllTasks(SingleThreadEventExecutor.java:343)
	at io.netty.channel.nio.NioEventLoop.run(NioEventLoop.java:356)
	at io.netty.util.concurrent.SingleThreadEventExecutor$5.run(SingleThreadEventExecutor.java:834)
	at io.netty.util.concurrent.DefaultThreadFactory$DefaultRunnableDecorator.run(DefaultThreadFactory.java:137)
	at java.lang.Thread.run(Unknown Source)
2015-03-24 17:27:37,539 INFO [io.netty.handler.logging.LoggingHandler] [id: 0xca6234f5, /0:0:0:0:0:0:0:0:8021] RECEIVED: [id: 0xab27c6ee, /127.0.0.1:57244 => /127.0.0.1:8021]
2015-03-24 17:28:03,548 WARN [io.netty.channel.DefaultChannelPipeline] An exceptionCaught() event was fired, and it reached at the tail of the pipeline. It usually means the last handler in the pipeline did not handle the exception.
io.netty.handler.timeout.ReadTimeoutException
2015-03-24 17:28:03,554 WARN [io.netty.channel.DefaultChannelPipeline] An exceptionCaught() event was fired, and it reached at the tail of the pipeline. It usually means the last handler in the pipeline did not handle the exception.
io.netty.handler.codec.DecoderException: java.lang.IndexOutOfBoundsException
	at io.netty.handler.codec.ByteToMessageDecoder.channelInactive(ByteToMessageDecoder.java:213)
	at io.netty.channel.ChannelHandlerInvokerUtil.invokeChannelInactiveNow(ChannelHandlerInvokerUtil.java:56)
	at io.netty.channel.DefaultChannelHandlerInvoker.invokeChannelInactive(DefaultChannelHandlerInvoker.java:92)
	at io.netty.channel.AbstractChannelHandlerContext.fireChannelInactive(AbstractChannelHandlerContext.java:160)
	at io.netty.channel.DefaultChannelPipeline.fireChannelInactive(DefaultChannelPipeline.java:868)
	at io.netty.channel.AbstractChannel$AbstractUnsafe$5.run(AbstractChannel.java:604)
	at io.netty.util.concurrent.SingleThreadEventExecutor.runAllTasks(SingleThreadEventExecutor.java:343)
	at io.netty.channel.nio.NioEventLoop.run(NioEventLoop.java:356)
	at io.netty.util.concurrent.SingleThreadEventExecutor$5.run(SingleThreadEventExecutor.java:834)
	at io.netty.util.concurrent.DefaultThreadFactory$DefaultRunnableDecorator.run(DefaultThreadFactory.java:137)
	at java.lang.Thread.run(Unknown Source)
Caused by: java.lang.IndexOutOfBoundsException
	at io.netty.buffer.EmptyByteBuf.readInt(EmptyByteBuf.java:470)
	at org.whale.inf.example.netty.common.NettyMessageDecoder.decode(NettyMessageDecoder.java:27)
	at io.netty.handler.codec.LengthFieldBasedFrameDecoder.decode(LengthFieldBasedFrameDecoder.java:343)
	at io.netty.handler.codec.ByteToMessageDecoder.decodeLast(ByteToMessageDecoder.java:304)
	at io.netty.handler.codec.ByteToMessageDecoder.channelInactive(ByteToMessageDecoder.java:208)
	... 10 more
2015-03-24 17:28:05,710 WARN [io.netty.channel.DefaultChannelPipeline] An exceptionCaught() event was fired, and it reached at the tail of the pipeline. It usually means the last handler in the pipeline did not handle the exception.
io.netty.handler.codec.DecoderException: java.lang.ClassCastException: java.lang.String cannot be cast to com.alibaba.fastjson.JSONObject
	at io.netty.handler.codec.ByteToMessageDecoder.callDecode(ByteToMessageDecoder.java:280)
	at io.netty.handler.codec.ByteToMessageDecoder.channelRead(ByteToMessageDecoder.java:149)
	at io.netty.channel.ChannelHandlerInvokerUtil.invokeChannelReadNow(ChannelHandlerInvokerUtil.java:83)
	at io.netty.channel.DefaultChannelHandlerInvoker.invokeChannelRead(DefaultChannelHandlerInvoker.java:153)
	at io.netty.channel.AbstractChannelHandlerContext.fireChannelRead(AbstractChannelHandlerContext.java:182)
	at io.netty.channel.DefaultChannelPipeline.fireChannelRead(DefaultChannelPipeline.java:886)
	at io.netty.channel.nio.AbstractNioByteChannel$NioByteUnsafe.read(AbstractNioByteChannel.java:126)
	at io.netty.channel.nio.NioEventLoop.processSelectedKey(NioEventLoop.java:510)
	at io.netty.channel.nio.NioEventLoop.processSelectedKeysOptimized(NioEventLoop.java:467)
	at io.netty.channel.nio.NioEventLoop.processSelectedKeys(NioEventLoop.java:381)
	at io.netty.channel.nio.NioEventLoop.run(NioEventLoop.java:353)
	at io.netty.util.concurrent.SingleThreadEventExecutor$5.run(SingleThreadEventExecutor.java:834)
	at io.netty.util.concurrent.DefaultThreadFactory$DefaultRunnableDecorator.run(DefaultThreadFactory.java:137)
	at java.lang.Thread.run(Unknown Source)
Caused by: java.lang.ClassCastException: java.lang.String cannot be cast to com.alibaba.fastjson.JSONObject
	at com.alibaba.fastjson.JSON.parseObject(JSON.java:169)
	at org.whale.inf.example.netty.common.NettyMessageDecoder.decode(NettyMessageDecoder.java:49)
	at io.netty.handler.codec.LengthFieldBasedFrameDecoder.decode(LengthFieldBasedFrameDecoder.java:343)
	at io.netty.handler.codec.ByteToMessageDecoder.callDecode(ByteToMessageDecoder.java:249)
	... 13 more
2015-03-24 17:28:05,711 WARN [io.netty.channel.DefaultChannelPipeline] An exceptionCaught() event was fired, and it reached at the tail of the pipeline. It usually means the last handler in the pipeline did not handle the exception.
io.netty.handler.timeout.ReadTimeoutException
2015-03-24 17:28:05,712 WARN [io.netty.channel.DefaultChannelPipeline] An exceptionCaught() event was fired, and it reached at the tail of the pipeline. It usually means the last handler in the pipeline did not handle the exception.
io.netty.handler.codec.TooLongFrameException: Adjusted frame length exceeds 1048576: 1885434747 - discarded
	at io.netty.handler.codec.LengthFieldBasedFrameDecoder.fail(LengthFieldBasedFrameDecoder.java:501)
	at io.netty.handler.codec.LengthFieldBasedFrameDecoder.failIfNecessary(LengthFieldBasedFrameDecoder.java:477)
	at io.netty.handler.codec.LengthFieldBasedFrameDecoder.decode(LengthFieldBasedFrameDecoder.java:403)
	at org.whale.inf.example.netty.common.NettyMessageDecoder.decode(NettyMessageDecoder.java:21)
	at io.netty.handler.codec.LengthFieldBasedFrameDecoder.decode(LengthFieldBasedFrameDecoder.java:343)
	at io.netty.handler.codec.ByteToMessageDecoder.callDecode(ByteToMessageDecoder.java:249)
	at io.netty.handler.codec.ByteToMessageDecoder.channelInactive(ByteToMessageDecoder.java:205)
	at io.netty.channel.ChannelHandlerInvokerUtil.invokeChannelInactiveNow(ChannelHandlerInvokerUtil.java:56)
	at io.netty.channel.DefaultChannelHandlerInvoker.invokeChannelInactive(DefaultChannelHandlerInvoker.java:92)
	at io.netty.channel.AbstractChannelHandlerContext.fireChannelInactive(AbstractChannelHandlerContext.java:160)
	at io.netty.channel.DefaultChannelPipeline.fireChannelInactive(DefaultChannelPipeline.java:868)
	at io.netty.channel.AbstractChannel$AbstractUnsafe$5.run(AbstractChannel.java:604)
	at io.netty.util.concurrent.SingleThreadEventExecutor.runAllTasks(SingleThreadEventExecutor.java:343)
	at io.netty.channel.nio.NioEventLoop.run(NioEventLoop.java:356)
	at io.netty.util.concurrent.SingleThreadEventExecutor$5.run(SingleThreadEventExecutor.java:834)
	at io.netty.util.concurrent.DefaultThreadFactory$DefaultRunnableDecorator.run(DefaultThreadFactory.java:137)
	at java.lang.Thread.run(Unknown Source)
2015-03-24 17:28:07,853 WARN [io.netty.channel.DefaultChannelPipeline] An exceptionCaught() event was fired, and it reached at the tail of the pipeline. It usually means the last handler in the pipeline did not handle the exception.
io.netty.handler.codec.DecoderException: java.lang.ClassCastException: java.lang.String cannot be cast to com.alibaba.fastjson.JSONObject
	at io.netty.handler.codec.ByteToMessageDecoder.callDecode(ByteToMessageDecoder.java:280)
	at io.netty.handler.codec.ByteToMessageDecoder.channelRead(ByteToMessageDecoder.java:149)
	at io.netty.channel.ChannelHandlerInvokerUtil.invokeChannelReadNow(ChannelHandlerInvokerUtil.java:83)
	at io.netty.channel.DefaultChannelHandlerInvoker.invokeChannelRead(DefaultChannelHandlerInvoker.java:153)
	at io.netty.channel.AbstractChannelHandlerContext.fireChannelRead(AbstractChannelHandlerContext.java:182)
	at io.netty.channel.DefaultChannelPipeline.fireChannelRead(DefaultChannelPipeline.java:886)
	at io.netty.channel.nio.AbstractNioByteChannel$NioByteUnsafe.read(AbstractNioByteChannel.java:126)
	at io.netty.channel.nio.NioEventLoop.processSelectedKey(NioEventLoop.java:510)
	at io.netty.channel.nio.NioEventLoop.processSelectedKeysOptimized(NioEventLoop.java:467)
	at io.netty.channel.nio.NioEventLoop.processSelectedKeys(NioEventLoop.java:381)
	at io.netty.channel.nio.NioEventLoop.run(NioEventLoop.java:353)
	at io.netty.util.concurrent.SingleThreadEventExecutor$5.run(SingleThreadEventExecutor.java:834)
	at io.netty.util.concurrent.DefaultThreadFactory$DefaultRunnableDecorator.run(DefaultThreadFactory.java:137)
	at java.lang.Thread.run(Unknown Source)
Caused by: java.lang.ClassCastException: java.lang.String cannot be cast to com.alibaba.fastjson.JSONObject
	at com.alibaba.fastjson.JSON.parseObject(JSON.java:169)
	at org.whale.inf.example.netty.common.NettyMessageDecoder.decode(NettyMessageDecoder.java:49)
	at io.netty.handler.codec.LengthFieldBasedFrameDecoder.decode(LengthFieldBasedFrameDecoder.java:343)
	at io.netty.handler.codec.ByteToMessageDecoder.callDecode(ByteToMessageDecoder.java:249)
	... 13 more
2015-03-24 17:28:08,561 INFO [io.netty.handler.logging.LoggingHandler] [id: 0xca6234f5, /0:0:0:0:0:0:0:0:8021] RECEIVED: [id: 0xcec56fbd, /127.0.0.1:57245 => /127.0.0.1:8021]
2015-03-24 17:28:11,597 WARN [io.netty.channel.DefaultChannelPipeline] An exceptionCaught() event was fired, and it reached at the tail of the pipeline. It usually means the last handler in the pipeline did not handle the exception.
java.io.IOException: 远程主机强迫关闭了一个现有的连接。
	at sun.nio.ch.SocketDispatcher.read0(Native Method)
	at sun.nio.ch.SocketDispatcher.read(Unknown Source)
	at sun.nio.ch.IOUtil.readIntoNativeBuffer(Unknown Source)
	at sun.nio.ch.IOUtil.read(Unknown Source)
	at sun.nio.ch.SocketChannelImpl.read(Unknown Source)
	at io.netty.buffer.PooledUnsafeDirectByteBuf.setBytes(PooledUnsafeDirectByteBuf.java:311)
	at io.netty.buffer.AbstractByteBuf.writeBytes(AbstractByteBuf.java:853)
	at io.netty.channel.socket.nio.NioSocketChannel.doReadBytes(NioSocketChannel.java:225)
	at io.netty.channel.nio.AbstractNioByteChannel$NioByteUnsafe.read(AbstractNioByteChannel.java:115)
	at io.netty.channel.nio.NioEventLoop.processSelectedKey(NioEventLoop.java:510)
	at io.netty.channel.nio.NioEventLoop.processSelectedKeysOptimized(NioEventLoop.java:467)
	at io.netty.channel.nio.NioEventLoop.processSelectedKeys(NioEventLoop.java:381)
	at io.netty.channel.nio.NioEventLoop.run(NioEventLoop.java:353)
	at io.netty.util.concurrent.SingleThreadEventExecutor$5.run(SingleThreadEventExecutor.java:834)
	at io.netty.util.concurrent.DefaultThreadFactory$DefaultRunnableDecorator.run(DefaultThreadFactory.java:137)
	at java.lang.Thread.run(Unknown Source)
2015-03-24 17:28:11,599 WARN [io.netty.channel.DefaultChannelPipeline] An exceptionCaught() event was fired, and it reached at the tail of the pipeline. It usually means the last handler in the pipeline did not handle the exception.
io.netty.handler.codec.DecoderException: java.lang.IndexOutOfBoundsException
	at io.netty.handler.codec.ByteToMessageDecoder.channelInactive(ByteToMessageDecoder.java:213)
	at io.netty.channel.ChannelHandlerInvokerUtil.invokeChannelInactiveNow(ChannelHandlerInvokerUtil.java:56)
	at io.netty.channel.DefaultChannelHandlerInvoker.invokeChannelInactive(DefaultChannelHandlerInvoker.java:92)
	at io.netty.channel.AbstractChannelHandlerContext.fireChannelInactive(AbstractChannelHandlerContext.java:160)
	at io.netty.channel.DefaultChannelPipeline.fireChannelInactive(DefaultChannelPipeline.java:868)
	at io.netty.channel.AbstractChannel$AbstractUnsafe$5.run(AbstractChannel.java:604)
	at io.netty.util.concurrent.SingleThreadEventExecutor.runAllTasks(SingleThreadEventExecutor.java:343)
	at io.netty.channel.nio.NioEventLoop.run(NioEventLoop.java:356)
	at io.netty.util.concurrent.SingleThreadEventExecutor$5.run(SingleThreadEventExecutor.java:834)
	at io.netty.util.concurrent.DefaultThreadFactory$DefaultRunnableDecorator.run(DefaultThreadFactory.java:137)
	at java.lang.Thread.run(Unknown Source)
Caused by: java.lang.IndexOutOfBoundsException
	at io.netty.buffer.EmptyByteBuf.readInt(EmptyByteBuf.java:470)
	at org.whale.inf.example.netty.common.NettyMessageDecoder.decode(NettyMessageDecoder.java:27)
	at io.netty.handler.codec.LengthFieldBasedFrameDecoder.decode(LengthFieldBasedFrameDecoder.java:343)
	at io.netty.handler.codec.ByteToMessageDecoder.decodeLast(ByteToMessageDecoder.java:304)
	at io.netty.handler.codec.ByteToMessageDecoder.channelInactive(ByteToMessageDecoder.java:208)
	... 10 more
2015-03-24 17:28:11,601 WARN [io.netty.channel.DefaultChannelPipeline] An exceptionCaught() event was fired, and it reached at the tail of the pipeline. It usually means the last handler in the pipeline did not handle the exception.
java.io.IOException: 远程主机强迫关闭了一个现有的连接。
	at sun.nio.ch.SocketDispatcher.read0(Native Method)
	at sun.nio.ch.SocketDispatcher.read(Unknown Source)
	at sun.nio.ch.IOUtil.readIntoNativeBuffer(Unknown Source)
	at sun.nio.ch.IOUtil.read(Unknown Source)
	at sun.nio.ch.SocketChannelImpl.read(Unknown Source)
	at io.netty.buffer.PooledUnsafeDirectByteBuf.setBytes(PooledUnsafeDirectByteBuf.java:311)
	at io.netty.buffer.AbstractByteBuf.writeBytes(AbstractByteBuf.java:853)
	at io.netty.channel.socket.nio.NioSocketChannel.doReadBytes(NioSocketChannel.java:225)
	at io.netty.channel.nio.AbstractNioByteChannel$NioByteUnsafe.read(AbstractNioByteChannel.java:115)
	at io.netty.channel.nio.NioEventLoop.processSelectedKey(NioEventLoop.java:510)
	at io.netty.channel.nio.NioEventLoop.processSelectedKeysOptimized(NioEventLoop.java:467)
	at io.netty.channel.nio.NioEventLoop.processSelectedKeys(NioEventLoop.java:381)
	at io.netty.channel.nio.NioEventLoop.run(NioEventLoop.java:353)
	at io.netty.util.concurrent.SingleThreadEventExecutor$5.run(SingleThreadEventExecutor.java:834)
	at io.netty.util.concurrent.DefaultThreadFactory$DefaultRunnableDecorator.run(DefaultThreadFactory.java:137)
	at java.lang.Thread.run(Unknown Source)
2015-03-24 17:28:11,602 WARN [io.netty.channel.DefaultChannelPipeline] An exceptionCaught() event was fired, and it reached at the tail of the pipeline. It usually means the last handler in the pipeline did not handle the exception.
io.netty.handler.codec.DecoderException: java.lang.IndexOutOfBoundsException
	at io.netty.handler.codec.ByteToMessageDecoder.channelInactive(ByteToMessageDecoder.java:213)
	at io.netty.channel.ChannelHandlerInvokerUtil.invokeChannelInactiveNow(ChannelHandlerInvokerUtil.java:56)
	at io.netty.channel.DefaultChannelHandlerInvoker.invokeChannelInactive(DefaultChannelHandlerInvoker.java:92)
	at io.netty.channel.AbstractChannelHandlerContext.fireChannelInactive(AbstractChannelHandlerContext.java:160)
	at io.netty.channel.DefaultChannelPipeline.fireChannelInactive(DefaultChannelPipeline.java:868)
	at io.netty.channel.AbstractChannel$AbstractUnsafe$5.run(AbstractChannel.java:604)
	at io.netty.util.concurrent.SingleThreadEventExecutor.runAllTasks(SingleThreadEventExecutor.java:343)
	at io.netty.channel.nio.NioEventLoop.run(NioEventLoop.java:356)
	at io.netty.util.concurrent.SingleThreadEventExecutor$5.run(SingleThreadEventExecutor.java:834)
	at io.netty.util.concurrent.DefaultThreadFactory$DefaultRunnableDecorator.run(DefaultThreadFactory.java:137)
	at java.lang.Thread.run(Unknown Source)
Caused by: java.lang.IndexOutOfBoundsException
	at io.netty.buffer.EmptyByteBuf.readInt(EmptyByteBuf.java:470)
	at org.whale.inf.example.netty.common.NettyMessageDecoder.decode(NettyMessageDecoder.java:27)
	at io.netty.handler.codec.LengthFieldBasedFrameDecoder.decode(LengthFieldBasedFrameDecoder.java:343)
	at io.netty.handler.codec.ByteToMessageDecoder.decodeLast(ByteToMessageDecoder.java:304)
	at io.netty.handler.codec.ByteToMessageDecoder.channelInactive(ByteToMessageDecoder.java:208)
	... 10 more
2015-03-24 17:46:38,001 INFO [io.netty.handler.logging.LoggingHandler] [id: 0x56c34d62] REGISTERED
2015-03-24 17:46:38,004 INFO [io.netty.handler.logging.LoggingHandler] [id: 0x56c34d62] BIND: 0.0.0.0/0.0.0.0:8021
2015-03-24 17:46:38,009 INFO [io.netty.handler.logging.LoggingHandler] [id: 0x56c34d62, /0:0:0:0:0:0:0:0:8021] ACTIVE
2015-03-24 17:46:42,727 INFO [io.netty.handler.logging.LoggingHandler] [id: 0x56c34d62, /0:0:0:0:0:0:0:0:8021] RECEIVED: [id: 0x912042f4, /127.0.0.1:62786 => /127.0.0.1:8021]
2015-03-24 17:47:32,812 WARN [io.netty.channel.DefaultChannelPipeline] An exceptionCaught() event was fired, and it reached at the tail of the pipeline. It usually means the last handler in the pipeline did not handle the exception.
io.netty.handler.timeout.ReadTimeoutException
2015-03-24 17:47:32,815 WARN [io.netty.channel.DefaultChannelPipeline] An exceptionCaught() event was fired, and it reached at the tail of the pipeline. It usually means the last handler in the pipeline did not handle the exception.
io.netty.handler.codec.DecoderException: java.lang.IndexOutOfBoundsException
	at io.netty.handler.codec.ByteToMessageDecoder.channelInactive(ByteToMessageDecoder.java:213)
	at io.netty.channel.ChannelHandlerInvokerUtil.invokeChannelInactiveNow(ChannelHandlerInvokerUtil.java:56)
	at io.netty.channel.DefaultChannelHandlerInvoker.invokeChannelInactive(DefaultChannelHandlerInvoker.java:92)
	at io.netty.channel.AbstractChannelHandlerContext.fireChannelInactive(AbstractChannelHandlerContext.java:160)
	at io.netty.channel.DefaultChannelPipeline.fireChannelInactive(DefaultChannelPipeline.java:868)
	at io.netty.channel.AbstractChannel$AbstractUnsafe$5.run(AbstractChannel.java:604)
	at io.netty.util.concurrent.SingleThreadEventExecutor.runAllTasks(SingleThreadEventExecutor.java:343)
	at io.netty.channel.nio.NioEventLoop.run(NioEventLoop.java:356)
	at io.netty.util.concurrent.SingleThreadEventExecutor$5.run(SingleThreadEventExecutor.java:834)
	at io.netty.util.concurrent.DefaultThreadFactory$DefaultRunnableDecorator.run(DefaultThreadFactory.java:137)
	at java.lang.Thread.run(Unknown Source)
Caused by: java.lang.IndexOutOfBoundsException
	at io.netty.buffer.EmptyByteBuf.readInt(EmptyByteBuf.java:470)
	at org.whale.inf.example.netty.common.NettyMessageDecoder.decode(NettyMessageDecoder.java:27)
	at io.netty.handler.codec.LengthFieldBasedFrameDecoder.decode(LengthFieldBasedFrameDecoder.java:343)
	at io.netty.handler.codec.ByteToMessageDecoder.decodeLast(ByteToMessageDecoder.java:304)
	at io.netty.handler.codec.ByteToMessageDecoder.channelInactive(ByteToMessageDecoder.java:208)
	... 10 more
2015-03-24 17:47:32,818 WARN [io.netty.channel.DefaultChannelPipeline] An exceptionCaught() event was fired, and it reached at the tail of the pipeline. It usually means the last handler in the pipeline did not handle the exception.
io.netty.handler.codec.DecoderException: java.lang.IndexOutOfBoundsException
	at io.netty.handler.codec.ByteToMessageDecoder.channelInactive(ByteToMessageDecoder.java:213)
	at io.netty.channel.ChannelHandlerInvokerUtil.invokeChannelInactiveNow(ChannelHandlerInvokerUtil.java:56)
	at io.netty.channel.DefaultChannelHandlerInvoker.invokeChannelInactive(DefaultChannelHandlerInvoker.java:92)
	at io.netty.channel.AbstractChannelHandlerContext.fireChannelInactive(AbstractChannelHandlerContext.java:160)
	at io.netty.channel.DefaultChannelPipeline.fireChannelInactive(DefaultChannelPipeline.java:868)
	at io.netty.channel.AbstractChannel$AbstractUnsafe$5.run(AbstractChannel.java:604)
	at io.netty.util.concurrent.SingleThreadEventExecutor.runAllTasks(SingleThreadEventExecutor.java:343)
	at io.netty.channel.nio.NioEventLoop.run(NioEventLoop.java:356)
	at io.netty.util.concurrent.SingleThreadEventExecutor$5.run(SingleThreadEventExecutor.java:834)
	at io.netty.util.concurrent.DefaultThreadFactory$DefaultRunnableDecorator.run(DefaultThreadFactory.java:137)
	at java.lang.Thread.run(Unknown Source)
Caused by: java.lang.IndexOutOfBoundsException
	at io.netty.buffer.EmptyByteBuf.readInt(EmptyByteBuf.java:470)
	at org.whale.inf.example.netty.common.NettyMessageDecoder.decode(NettyMessageDecoder.java:27)
	at io.netty.handler.codec.LengthFieldBasedFrameDecoder.decode(LengthFieldBasedFrameDecoder.java:343)
	at io.netty.handler.codec.ByteToMessageDecoder.decodeLast(ByteToMessageDecoder.java:304)
	at io.netty.handler.codec.ByteToMessageDecoder.channelInactive(ByteToMessageDecoder.java:208)
	... 10 more
2015-03-24 17:47:37,821 INFO [io.netty.handler.logging.LoggingHandler] [id: 0x56c34d62, /0:0:0:0:0:0:0:0:8021] RECEIVED: [id: 0x30454cc6, /127.0.0.1:62793 => /127.0.0.1:8021]
2015-03-24 17:48:27,831 WARN [io.netty.channel.DefaultChannelPipeline] An exceptionCaught() event was fired, and it reached at the tail of the pipeline. It usually means the last handler in the pipeline did not handle the exception.
io.netty.handler.timeout.ReadTimeoutException
2015-03-24 17:48:27,832 WARN [io.netty.channel.DefaultChannelPipeline] An exceptionCaught() event was fired, and it reached at the tail of the pipeline. It usually means the last handler in the pipeline did not handle the exception.
io.netty.handler.codec.DecoderException: java.lang.IndexOutOfBoundsException
	at io.netty.handler.codec.ByteToMessageDecoder.channelInactive(ByteToMessageDecoder.java:213)
	at io.netty.channel.ChannelHandlerInvokerUtil.invokeChannelInactiveNow(ChannelHandlerInvokerUtil.java:56)
	at io.netty.channel.DefaultChannelHandlerInvoker.invokeChannelInactive(DefaultChannelHandlerInvoker.java:92)
	at io.netty.channel.AbstractChannelHandlerContext.fireChannelInactive(AbstractChannelHandlerContext.java:160)
	at io.netty.channel.DefaultChannelPipeline.fireChannelInactive(DefaultChannelPipeline.java:868)
	at io.netty.channel.AbstractChannel$AbstractUnsafe$5.run(AbstractChannel.java:604)
	at io.netty.util.concurrent.SingleThreadEventExecutor.runAllTasks(SingleThreadEventExecutor.java:343)
	at io.netty.channel.nio.NioEventLoop.run(NioEventLoop.java:356)
	at io.netty.util.concurrent.SingleThreadEventExecutor$5.run(SingleThreadEventExecutor.java:834)
	at io.netty.util.concurrent.DefaultThreadFactory$DefaultRunnableDecorator.run(DefaultThreadFactory.java:137)
	at java.lang.Thread.run(Unknown Source)
Caused by: java.lang.IndexOutOfBoundsException
	at io.netty.buffer.EmptyByteBuf.readInt(EmptyByteBuf.java:470)
	at org.whale.inf.example.netty.common.NettyMessageDecoder.decode(NettyMessageDecoder.java:27)
	at io.netty.handler.codec.LengthFieldBasedFrameDecoder.decode(LengthFieldBasedFrameDecoder.java:343)
	at io.netty.handler.codec.ByteToMessageDecoder.decodeLast(ByteToMessageDecoder.java:304)
	at io.netty.handler.codec.ByteToMessageDecoder.channelInactive(ByteToMessageDecoder.java:208)
	... 10 more
2015-03-24 17:48:27,832 WARN [io.netty.channel.DefaultChannelPipeline] An exceptionCaught() event was fired, and it reached at the tail of the pipeline. It usually means the last handler in the pipeline did not handle the exception.
io.netty.handler.codec.DecoderException: java.lang.IndexOutOfBoundsException
	at io.netty.handler.codec.ByteToMessageDecoder.channelInactive(ByteToMessageDecoder.java:213)
	at io.netty.channel.ChannelHandlerInvokerUtil.invokeChannelInactiveNow(ChannelHandlerInvokerUtil.java:56)
	at io.netty.channel.DefaultChannelHandlerInvoker.invokeChannelInactive(DefaultChannelHandlerInvoker.java:92)
	at io.netty.channel.AbstractChannelHandlerContext.fireChannelInactive(AbstractChannelHandlerContext.java:160)
	at io.netty.channel.DefaultChannelPipeline.fireChannelInactive(DefaultChannelPipeline.java:868)
	at io.netty.channel.AbstractChannel$AbstractUnsafe$5.run(AbstractChannel.java:604)
	at io.netty.util.concurrent.SingleThreadEventExecutor.runAllTasks(SingleThreadEventExecutor.java:343)
	at io.netty.channel.nio.NioEventLoop.run(NioEventLoop.java:356)
	at io.netty.util.concurrent.SingleThreadEventExecutor$5.run(SingleThreadEventExecutor.java:834)
	at io.netty.util.concurrent.DefaultThreadFactory$DefaultRunnableDecorator.run(DefaultThreadFactory.java:137)
	at java.lang.Thread.run(Unknown Source)
Caused by: java.lang.IndexOutOfBoundsException
	at io.netty.buffer.EmptyByteBuf.readInt(EmptyByteBuf.java:470)
	at org.whale.inf.example.netty.common.NettyMessageDecoder.decode(NettyMessageDecoder.java:27)
	at io.netty.handler.codec.LengthFieldBasedFrameDecoder.decode(LengthFieldBasedFrameDecoder.java:343)
	at io.netty.handler.codec.ByteToMessageDecoder.decodeLast(ByteToMessageDecoder.java:304)
	at io.netty.handler.codec.ByteToMessageDecoder.channelInactive(ByteToMessageDecoder.java:208)
	... 10 more
2015-03-24 17:48:32,836 INFO [io.netty.handler.logging.LoggingHandler] [id: 0x56c34d62, /0:0:0:0:0:0:0:0:8021] RECEIVED: [id: 0x0c14b1df, /127.0.0.1:62801 => /127.0.0.1:8021]
2015-03-24 17:48:52,928 WARN [io.netty.channel.DefaultChannelPipeline] An exceptionCaught() event was fired, and it reached at the tail of the pipeline. It usually means the last handler in the pipeline did not handle the exception.
java.io.IOException: 远程主机强迫关闭了一个现有的连接。
	at sun.nio.ch.SocketDispatcher.read0(Native Method)
	at sun.nio.ch.SocketDispatcher.read(Unknown Source)
	at sun.nio.ch.IOUtil.readIntoNativeBuffer(Unknown Source)
	at sun.nio.ch.IOUtil.read(Unknown Source)
	at sun.nio.ch.SocketChannelImpl.read(Unknown Source)
	at io.netty.buffer.PooledUnsafeDirectByteBuf.setBytes(PooledUnsafeDirectByteBuf.java:311)
	at io.netty.buffer.AbstractByteBuf.writeBytes(AbstractByteBuf.java:853)
	at io.netty.channel.socket.nio.NioSocketChannel.doReadBytes(NioSocketChannel.java:225)
	at io.netty.channel.nio.AbstractNioByteChannel$NioByteUnsafe.read(AbstractNioByteChannel.java:115)
	at io.netty.channel.nio.NioEventLoop.processSelectedKey(NioEventLoop.java:510)
	at io.netty.channel.nio.NioEventLoop.processSelectedKeysOptimized(NioEventLoop.java:467)
	at io.netty.channel.nio.NioEventLoop.processSelectedKeys(NioEventLoop.java:381)
	at io.netty.channel.nio.NioEventLoop.run(NioEventLoop.java:353)
	at io.netty.util.concurrent.SingleThreadEventExecutor$5.run(SingleThreadEventExecutor.java:834)
	at io.netty.util.concurrent.DefaultThreadFactory$DefaultRunnableDecorator.run(DefaultThreadFactory.java:137)
	at java.lang.Thread.run(Unknown Source)
2015-03-24 17:48:52,930 WARN [io.netty.channel.DefaultChannelPipeline] An exceptionCaught() event was fired, and it reached at the tail of the pipeline. It usually means the last handler in the pipeline did not handle the exception.
io.netty.handler.codec.DecoderException: java.lang.IndexOutOfBoundsException
	at io.netty.handler.codec.ByteToMessageDecoder.channelInactive(ByteToMessageDecoder.java:213)
	at io.netty.channel.ChannelHandlerInvokerUtil.invokeChannelInactiveNow(ChannelHandlerInvokerUtil.java:56)
	at io.netty.channel.DefaultChannelHandlerInvoker.invokeChannelInactive(DefaultChannelHandlerInvoker.java:92)
	at io.netty.channel.AbstractChannelHandlerContext.fireChannelInactive(AbstractChannelHandlerContext.java:160)
	at io.netty.channel.DefaultChannelPipeline.fireChannelInactive(DefaultChannelPipeline.java:868)
	at io.netty.channel.AbstractChannel$AbstractUnsafe$5.run(AbstractChannel.java:604)
	at io.netty.util.concurrent.SingleThreadEventExecutor.runAllTasks(SingleThreadEventExecutor.java:343)
	at io.netty.channel.nio.NioEventLoop.run(NioEventLoop.java:356)
	at io.netty.util.concurrent.SingleThreadEventExecutor$5.run(SingleThreadEventExecutor.java:834)
	at io.netty.util.concurrent.DefaultThreadFactory$DefaultRunnableDecorator.run(DefaultThreadFactory.java:137)
	at java.lang.Thread.run(Unknown Source)
Caused by: java.lang.IndexOutOfBoundsException
	at io.netty.buffer.EmptyByteBuf.readInt(EmptyByteBuf.java:470)
	at org.whale.inf.example.netty.common.NettyMessageDecoder.decode(NettyMessageDecoder.java:27)
	at io.netty.handler.codec.LengthFieldBasedFrameDecoder.decode(LengthFieldBasedFrameDecoder.java:343)
	at io.netty.handler.codec.ByteToMessageDecoder.decodeLast(ByteToMessageDecoder.java:304)
	at io.netty.handler.codec.ByteToMessageDecoder.channelInactive(ByteToMessageDecoder.java:208)
	... 10 more
2015-03-24 17:52:18,498 INFO [io.netty.handler.logging.LoggingHandler] [id: 0x3d1ec2f1] REGISTERED
2015-03-24 17:52:18,500 INFO [io.netty.handler.logging.LoggingHandler] [id: 0x3d1ec2f1] BIND: 0.0.0.0/0.0.0.0:8021
2015-03-24 17:52:18,504 INFO [io.netty.handler.logging.LoggingHandler] [id: 0x3d1ec2f1, /0:0:0:0:0:0:0:0:8021] ACTIVE
2015-03-24 17:52:23,734 INFO [io.netty.handler.logging.LoggingHandler] [id: 0x3d1ec2f1, /0:0:0:0:0:0:0:0:8021] RECEIVED: [id: 0x71abea84, /127.0.0.1:52019 => /127.0.0.1:8021]
2015-03-24 17:53:13,819 WARN [io.netty.channel.DefaultChannelPipeline] An exceptionCaught() event was fired, and it reached at the tail of the pipeline. It usually means the last handler in the pipeline did not handle the exception.
io.netty.handler.timeout.ReadTimeoutException
2015-03-24 17:53:13,825 WARN [io.netty.channel.DefaultChannelPipeline] An exceptionCaught() event was fired, and it reached at the tail of the pipeline. It usually means the last handler in the pipeline did not handle the exception.
io.netty.handler.codec.DecoderException: java.lang.IndexOutOfBoundsException
	at io.netty.handler.codec.ByteToMessageDecoder.channelInactive(ByteToMessageDecoder.java:213)
	at io.netty.channel.ChannelHandlerInvokerUtil.invokeChannelInactiveNow(ChannelHandlerInvokerUtil.java:56)
	at io.netty.channel.DefaultChannelHandlerInvoker.invokeChannelInactive(DefaultChannelHandlerInvoker.java:92)
	at io.netty.channel.AbstractChannelHandlerContext.fireChannelInactive(AbstractChannelHandlerContext.java:160)
	at io.netty.channel.DefaultChannelPipeline.fireChannelInactive(DefaultChannelPipeline.java:868)
	at io.netty.channel.AbstractChannel$AbstractUnsafe$5.run(AbstractChannel.java:604)
	at io.netty.util.concurrent.SingleThreadEventExecutor.runAllTasks(SingleThreadEventExecutor.java:343)
	at io.netty.channel.nio.NioEventLoop.run(NioEventLoop.java:356)
	at io.netty.util.concurrent.SingleThreadEventExecutor$5.run(SingleThreadEventExecutor.java:834)
	at io.netty.util.concurrent.DefaultThreadFactory$DefaultRunnableDecorator.run(DefaultThreadFactory.java:137)
	at java.lang.Thread.run(Unknown Source)
Caused by: java.lang.IndexOutOfBoundsException
	at io.netty.buffer.EmptyByteBuf.readInt(EmptyByteBuf.java:470)
	at org.whale.inf.example.netty.common.NettyMessageDecoder.decode(NettyMessageDecoder.java:27)
	at io.netty.handler.codec.LengthFieldBasedFrameDecoder.decode(LengthFieldBasedFrameDecoder.java:343)
	at io.netty.handler.codec.ByteToMessageDecoder.decodeLast(ByteToMessageDecoder.java:304)
	at io.netty.handler.codec.ByteToMessageDecoder.channelInactive(ByteToMessageDecoder.java:208)
	... 10 more
2015-03-24 17:53:13,828 WARN [io.netty.channel.DefaultChannelPipeline] An exceptionCaught() event was fired, and it reached at the tail of the pipeline. It usually means the last handler in the pipeline did not handle the exception.
io.netty.handler.codec.DecoderException: java.lang.IndexOutOfBoundsException
	at io.netty.handler.codec.ByteToMessageDecoder.channelInactive(ByteToMessageDecoder.java:213)
	at io.netty.channel.ChannelHandlerInvokerUtil.invokeChannelInactiveNow(ChannelHandlerInvokerUtil.java:56)
	at io.netty.channel.DefaultChannelHandlerInvoker.invokeChannelInactive(DefaultChannelHandlerInvoker.java:92)
	at io.netty.channel.AbstractChannelHandlerContext.fireChannelInactive(AbstractChannelHandlerContext.java:160)
	at io.netty.channel.DefaultChannelPipeline.fireChannelInactive(DefaultChannelPipeline.java:868)
	at io.netty.channel.AbstractChannel$AbstractUnsafe$5.run(AbstractChannel.java:604)
	at io.netty.util.concurrent.SingleThreadEventExecutor.runAllTasks(SingleThreadEventExecutor.java:343)
	at io.netty.channel.nio.NioEventLoop.run(NioEventLoop.java:356)
	at io.netty.util.concurrent.SingleThreadEventExecutor$5.run(SingleThreadEventExecutor.java:834)
	at io.netty.util.concurrent.DefaultThreadFactory$DefaultRunnableDecorator.run(DefaultThreadFactory.java:137)
	at java.lang.Thread.run(Unknown Source)
Caused by: java.lang.IndexOutOfBoundsException
	at io.netty.buffer.EmptyByteBuf.readInt(EmptyByteBuf.java:470)
	at org.whale.inf.example.netty.common.NettyMessageDecoder.decode(NettyMessageDecoder.java:27)
	at io.netty.handler.codec.LengthFieldBasedFrameDecoder.decode(LengthFieldBasedFrameDecoder.java:343)
	at io.netty.handler.codec.ByteToMessageDecoder.decodeLast(ByteToMessageDecoder.java:304)
	at io.netty.handler.codec.ByteToMessageDecoder.channelInactive(ByteToMessageDecoder.java:208)
	... 10 more
2015-03-24 17:53:18,841 INFO [io.netty.handler.logging.LoggingHandler] [id: 0x3d1ec2f1, /0:0:0:0:0:0:0:0:8021] RECEIVED: [id: 0x90bc80f0, /127.0.0.1:52036 => /127.0.0.1:8021]
2015-03-24 17:53:39,048 WARN [io.netty.channel.DefaultChannelPipeline] An exceptionCaught() event was fired, and it reached at the tail of the pipeline. It usually means the last handler in the pipeline did not handle the exception.
java.io.IOException: 远程主机强迫关闭了一个现有的连接。
	at sun.nio.ch.SocketDispatcher.read0(Native Method)
	at sun.nio.ch.SocketDispatcher.read(Unknown Source)
	at sun.nio.ch.IOUtil.readIntoNativeBuffer(Unknown Source)
	at sun.nio.ch.IOUtil.read(Unknown Source)
	at sun.nio.ch.SocketChannelImpl.read(Unknown Source)
	at io.netty.buffer.PooledUnsafeDirectByteBuf.setBytes(PooledUnsafeDirectByteBuf.java:311)
	at io.netty.buffer.AbstractByteBuf.writeBytes(AbstractByteBuf.java:853)
	at io.netty.channel.socket.nio.NioSocketChannel.doReadBytes(NioSocketChannel.java:225)
	at io.netty.channel.nio.AbstractNioByteChannel$NioByteUnsafe.read(AbstractNioByteChannel.java:115)
	at io.netty.channel.nio.NioEventLoop.processSelectedKey(NioEventLoop.java:510)
	at io.netty.channel.nio.NioEventLoop.processSelectedKeysOptimized(NioEventLoop.java:467)
	at io.netty.channel.nio.NioEventLoop.processSelectedKeys(NioEventLoop.java:381)
	at io.netty.channel.nio.NioEventLoop.run(NioEventLoop.java:353)
	at io.netty.util.concurrent.SingleThreadEventExecutor$5.run(SingleThreadEventExecutor.java:834)
	at io.netty.util.concurrent.DefaultThreadFactory$DefaultRunnableDecorator.run(DefaultThreadFactory.java:137)
	at java.lang.Thread.run(Unknown Source)
2015-03-24 17:53:39,049 WARN [io.netty.channel.DefaultChannelPipeline] An exceptionCaught() event was fired, and it reached at the tail of the pipeline. It usually means the last handler in the pipeline did not handle the exception.
io.netty.handler.codec.DecoderException: java.lang.IndexOutOfBoundsException
	at io.netty.handler.codec.ByteToMessageDecoder.channelInactive(ByteToMessageDecoder.java:213)
	at io.netty.channel.ChannelHandlerInvokerUtil.invokeChannelInactiveNow(ChannelHandlerInvokerUtil.java:56)
	at io.netty.channel.DefaultChannelHandlerInvoker.invokeChannelInactive(DefaultChannelHandlerInvoker.java:92)
	at io.netty.channel.AbstractChannelHandlerContext.fireChannelInactive(AbstractChannelHandlerContext.java:160)
	at io.netty.channel.DefaultChannelPipeline.fireChannelInactive(DefaultChannelPipeline.java:868)
	at io.netty.channel.AbstractChannel$AbstractUnsafe$5.run(AbstractChannel.java:604)
	at io.netty.util.concurrent.SingleThreadEventExecutor.runAllTasks(SingleThreadEventExecutor.java:343)
	at io.netty.channel.nio.NioEventLoop.run(NioEventLoop.java:356)
	at io.netty.util.concurrent.SingleThreadEventExecutor$5.run(SingleThreadEventExecutor.java:834)
	at io.netty.util.concurrent.DefaultThreadFactory$DefaultRunnableDecorator.run(DefaultThreadFactory.java:137)
	at java.lang.Thread.run(Unknown Source)
Caused by: java.lang.IndexOutOfBoundsException
	at io.netty.buffer.EmptyByteBuf.readInt(EmptyByteBuf.java:470)
	at org.whale.inf.example.netty.common.NettyMessageDecoder.decode(NettyMessageDecoder.java:27)
	at io.netty.handler.codec.LengthFieldBasedFrameDecoder.decode(LengthFieldBasedFrameDecoder.java:343)
	at io.netty.handler.codec.ByteToMessageDecoder.decodeLast(ByteToMessageDecoder.java:304)
	at io.netty.handler.codec.ByteToMessageDecoder.channelInactive(ByteToMessageDecoder.java:208)
	... 10 more
2015-03-24 17:55:01,056 INFO [io.netty.handler.logging.LoggingHandler] [id: 0xe449ac16] REGISTERED
2015-03-24 17:55:01,058 INFO [io.netty.handler.logging.LoggingHandler] [id: 0xe449ac16] BIND: 0.0.0.0/0.0.0.0:8021
2015-03-24 17:55:01,062 INFO [io.netty.handler.logging.LoggingHandler] [id: 0xe449ac16, /0:0:0:0:0:0:0:0:8021] ACTIVE
2015-03-24 17:55:07,985 INFO [io.netty.handler.logging.LoggingHandler] [id: 0xe449ac16, /0:0:0:0:0:0:0:0:8021] RECEIVED: [id: 0x169d2c28, /127.0.0.1:61655 => /127.0.0.1:8021]
2015-03-24 17:55:27,475 WARN [io.netty.channel.DefaultChannelPipeline] An exceptionCaught() event was fired, and it reached at the tail of the pipeline. It usually means the last handler in the pipeline did not handle the exception.
java.io.IOException: 远程主机强迫关闭了一个现有的连接。
	at sun.nio.ch.SocketDispatcher.read0(Native Method)
	at sun.nio.ch.SocketDispatcher.read(Unknown Source)
	at sun.nio.ch.IOUtil.readIntoNativeBuffer(Unknown Source)
	at sun.nio.ch.IOUtil.read(Unknown Source)
	at sun.nio.ch.SocketChannelImpl.read(Unknown Source)
	at io.netty.buffer.PooledUnsafeDirectByteBuf.setBytes(PooledUnsafeDirectByteBuf.java:311)
	at io.netty.buffer.AbstractByteBuf.writeBytes(AbstractByteBuf.java:853)
	at io.netty.channel.socket.nio.NioSocketChannel.doReadBytes(NioSocketChannel.java:225)
	at io.netty.channel.nio.AbstractNioByteChannel$NioByteUnsafe.read(AbstractNioByteChannel.java:115)
	at io.netty.channel.nio.NioEventLoop.processSelectedKey(NioEventLoop.java:510)
	at io.netty.channel.nio.NioEventLoop.processSelectedKeysOptimized(NioEventLoop.java:467)
	at io.netty.channel.nio.NioEventLoop.processSelectedKeys(NioEventLoop.java:381)
	at io.netty.channel.nio.NioEventLoop.run(NioEventLoop.java:353)
	at io.netty.util.concurrent.SingleThreadEventExecutor$5.run(SingleThreadEventExecutor.java:834)
	at io.netty.util.concurrent.DefaultThreadFactory$DefaultRunnableDecorator.run(DefaultThreadFactory.java:137)
	at java.lang.Thread.run(Unknown Source)
2015-03-24 17:55:27,490 WARN [io.netty.channel.DefaultChannelPipeline] An exceptionCaught() event was fired, and it reached at the tail of the pipeline. It usually means the last handler in the pipeline did not handle the exception.
io.netty.handler.codec.DecoderException: java.lang.IndexOutOfBoundsException
	at io.netty.handler.codec.ByteToMessageDecoder.channelInactive(ByteToMessageDecoder.java:213)
	at io.netty.channel.ChannelHandlerInvokerUtil.invokeChannelInactiveNow(ChannelHandlerInvokerUtil.java:56)
	at io.netty.channel.DefaultChannelHandlerInvoker.invokeChannelInactive(DefaultChannelHandlerInvoker.java:92)
	at io.netty.channel.AbstractChannelHandlerContext.fireChannelInactive(AbstractChannelHandlerContext.java:160)
	at io.netty.channel.DefaultChannelPipeline.fireChannelInactive(DefaultChannelPipeline.java:868)
	at io.netty.channel.AbstractChannel$AbstractUnsafe$5.run(AbstractChannel.java:604)
	at io.netty.util.concurrent.SingleThreadEventExecutor.runAllTasks(SingleThreadEventExecutor.java:343)
	at io.netty.channel.nio.NioEventLoop.run(NioEventLoop.java:356)
	at io.netty.util.concurrent.SingleThreadEventExecutor$5.run(SingleThreadEventExecutor.java:834)
	at io.netty.util.concurrent.DefaultThreadFactory$DefaultRunnableDecorator.run(DefaultThreadFactory.java:137)
	at java.lang.Thread.run(Unknown Source)
Caused by: java.lang.IndexOutOfBoundsException
	at io.netty.buffer.EmptyByteBuf.readInt(EmptyByteBuf.java:470)
	at org.whale.inf.example.netty.common.NettyMessageDecoder.decode(NettyMessageDecoder.java:27)
	at io.netty.handler.codec.LengthFieldBasedFrameDecoder.decode(LengthFieldBasedFrameDecoder.java:343)
	at io.netty.handler.codec.ByteToMessageDecoder.decodeLast(ByteToMessageDecoder.java:304)
	at io.netty.handler.codec.ByteToMessageDecoder.channelInactive(ByteToMessageDecoder.java:208)
	... 10 more
